data/btcusdt_l3_sample.csv
timestamp,event_type,order_id,side,price,quantity
1704067200000000000,ADD,1,BUY,41950.00,1
1704067200000100000,ADD,2,BUY,41950.00,9
1704067200000200000,ADD,3,BUY,41950.50,8
1704067200000300000,ADD,4,BUY,41950.50,5
1704067200000400000,ADD,5,BUY,41950.50,4
1704067200000500000,ADD,6,BUY,41951.00,19
1704067200000600000,ADD,7,BUY,41951.00,14
1704067200000700000,ADD,8,BUY,41951.50,1
1704067200000800000,ADD,9,BUY,41951.50,3
1704067200000900000,ADD,10,BUY,41952.00,8
1704067200001000000,ADD,11,BUY,41952.00,17
1704067200001100000,ADD,12,BUY,41952.00,20
1704067200001200000,ADD,13,BUY,41952.50,18
1704067200001300000,ADD,14,BUY,41952.50,7
1704067200001400000,ADD,15,BUY,41953.00,8
1704067200001500000,ADD,16,BUY,41953.00,15
1704067200001600000,ADD,17,BUY,41953.00,19
1704067200001700000,ADD,18,BUY,41953.00,9
1704067200001800000,ADD,19,BUY,41953.00,1
1704067200001900000,ADD,20,BUY,41953.50,14
1704067200002000000,ADD,21,BUY,41953.50,11
1704067200002100000,ADD,22,BUY,41953.50,9
1704067200002200000,ADD,23,BUY,41954.00,7
1704067200002300000,ADD,24,BUY,41954.00,11
1704067200002400000,ADD,25,BUY,41954.00,4
1704067200002500000,ADD,26,BUY,41954.50,13
1704067200002600000,ADD,27,BUY,41954.50,4
1704067200002700000,ADD,28,BUY,41955.00,12
1704067200002800000,ADD,29,BUY,41955.00,20
1704067200002900000,ADD,30,BUY,41955.00,9
1704067200003000000,ADD,31,BUY,41955.00,2
1704067200003100000,ADD,32,BUY,41955.50,18
1704067200003200000,ADD,33,BUY,41955.50,4
1704067200003300000,ADD,34,BUY,41955.50,13
1704067200003400000,ADD,35,BUY,41955.50,3
1704067200003500000,ADD,36,BUY,41955.50,18
1704067200003600000,ADD,37,BUY,41956.00,20
1704067200003700000,ADD,38,BUY,41956.00,12
1704067200003800000,ADD,39,BUY,41956.00,19
1704067200003900000,ADD,40,BUY,41956.00,7
1704067200004000000,ADD,41,BUY,41956.50,2
1704067200004100000,ADD,42,BUY,41956.50,8
1704067200004200000,ADD,43,BUY,41957.00,3
1704067200004300000,ADD,44,BUY,41957.00,8
1704067200004400000,ADD,45,BUY,41957.00,4
1704067200004500000,ADD,46,BUY,41957.00,13
1704067200004600000,ADD,47,BUY,41957.50,15
1704067200004700000,ADD,48,BUY,41957.50,12
1704067200004800000,ADD,49,BUY,41957.50,6
1704067200004900000,ADD,50,BUY,41957.50,12
1704067200005000000,ADD,51,BUY,41958.00,7
1704067200005100000,ADD,52,BUY,41958.00,9
1704067200005200000,ADD,53,BUY,41958.00,3
1704067200005300000,ADD,54,BUY,41958.00,20
1704067200005400000,ADD,55,BUY,41958.50,18
1704067200005500000,ADD,56,BUY,41958.50,8
1704067200005600000,ADD,57,BUY,41958.50,6
1704067200005700000,ADD,58,BUY,41959.00,13
1704067200005800000,ADD,59,BUY,41959.00,9
1704067200005900000,ADD,60,BUY,41959.00,18
1704067200006000000,ADD,61,BUY,41959.00,8
1704067200006100000,ADD,62,BUY,41959.00,11
1704067200006200000,ADD,63,BUY,41959.50,8
1704067200006300000,ADD,64,BUY,41959.50,2
1704067200006400000,ADD,65,BUY,41960.00,13
1704067200006500000,ADD,66,BUY,41960.00,9
1704067200006600000,ADD,67,BUY,41960.00,3
1704067200006700000,ADD,68,BUY,41960.00,7
1704067200006800000,ADD,69,BUY,41960.50,7
1704067200006900000,ADD,70,BUY,41960.50,16
1704067200007000000,ADD,71,BUY,41960.50,13
1704067200007100000,ADD,72,BUY,41960.50,15
1704067200007200000,ADD,73,BUY,41961.00,9
1704067200007300000,ADD,74,BUY,41961.00,5
1704067200007400000,ADD,75,BUY,41961.00,8
1704067200007500000,ADD,76,BUY,41961.50,19
1704067200007600000,ADD,77,BUY,41961.50,14
1704067200007700000,ADD,78,BUY,41961.50,19
1704067200007800000,ADD,79,BUY,41961.50,13
1704067200007900000,ADD,80,BUY,41962.00,8
1704067200008000000,ADD,81,BUY,41962.00,5
1704067200008100000,ADD,82,BUY,41962.00,17
1704067200008200000,ADD,83,BUY,41962.00,16
1704067200008300000,ADD,84,BUY,41962.50,2
1704067200008400000,ADD,85,BUY,41962.50,4
1704067200008500000,ADD,86,BUY,41963.00,6
1704067200008600000,ADD,87,BUY,41963.00,14
1704067200008700000,ADD,88,BUY,41963.00,20
1704067200008800000,ADD,89,BUY,41963.50,13
1704067200008900000,ADD,90,BUY,41963.50,13
1704067200009000000,ADD,91,BUY,41964.00,17
1704067200009100000,ADD,92,BUY,41964.00,9
1704067200009200000,ADD,93,BUY,41964.00,18
1704067200009300000,ADD,94,BUY,41964.00,1
1704067200009400000,ADD,95,BUY,41964.00,4
1704067200009500000,ADD,96,BUY,41964.50,11
1704067200009600000,ADD,97,BUY,41964.50,4
1704067200009700000,ADD,98,BUY,41964.50,10
1704067200009800000,ADD,99,BUY,41964.50,14
1704067200009900000,ADD,100,BUY,41965.00,15
1704067200010000000,ADD,101,BUY,41965.00,1
1704067200010100000,ADD,102,BUY,41965.00,9
1704067200010200000,ADD,103,BUY,41965.50,17
1704067200010300000,ADD,104,BUY,41965.50,4
1704067200010400000,ADD,105,BUY,41965.50,10
1704067200010500000,ADD,106,BUY,41966.00,5
1704067200010600000,ADD,107,BUY,41966.00,12
1704067200010700000,ADD,108,BUY,41966.00,6
1704067200010800000,ADD,109,BUY,41966.50,20
1704067200010900000,ADD,110,BUY,41966.50,11
1704067200011000000,ADD,111,BUY,41967.00,1
1704067200011100000,ADD,112,BUY,41967.00,4
1704067200011200000,ADD,113,BUY,41967.00,12
1704067200011300000,ADD,114,BUY,41967.00,10
1704067200011400000,ADD,115,BUY,41967.00,8
1704067200011500000,ADD,116,BUY,41967.50,8
1704067200011600000,ADD,117,BUY,41967.50,19
1704067200011700000,ADD,118,BUY,41968.00,3
1704067200011800000,ADD,119,BUY,41968.00,16
1704067200011900000,ADD,120,BUY,41968.50,18
1704067200012000000,ADD,121,BUY,41968.50,5
1704067200012100000,ADD,122,BUY,41969.00,16
1704067200012200000,ADD,123,BUY,41969.00,18
1704067200012300000,ADD,124,BUY,41969.00,6
1704067200012400000,ADD,125,BUY,41969.50,17
1704067200012500000,ADD,126,BUY,41969.50,20
1704067200012600000,ADD,127,BUY,41969.50,14
1704067200012700000,ADD,128,BUY,41969.50,7
1704067200012800000,ADD,129,BUY,41970.00,10
1704067200012900000,ADD,130,BUY,41970.00,13
1704067200013000000,ADD,131,BUY,41970.00,12
1704067200013100000,ADD,132,BUY,41970.50,17
1704067200013200000,ADD,133,BUY,41970.50,15
1704067200013300000,ADD,134,BUY,41970.50,4
1704067200013400000,ADD,135,BUY,41970.50,8
1704067200013500000,ADD,136,BUY,41970.50,8
1704067200013600000,ADD,137,BUY,41971.00,11
1704067200013700000,ADD,138,BUY,41971.00,1
1704067200013800000,ADD,139,BUY,41971.50,19
1704067200013900000,ADD,140,BUY,41971.50,8
1704067200014000000,ADD,141,BUY,41971.50,1
1704067200014100000,ADD,142,BUY,41972.00,2
1704067200014200000,ADD,143,BUY,41972.00,8
1704067200014300000,ADD,144,BUY,41972.50,2
1704067200014400000,ADD,145,BUY,41972.50,11
1704067200014500000,ADD,146,BUY,41973.00,17
1704067200014600000,ADD,147,BUY,41973.00,8
1704067200014700000,ADD,148,BUY,41973.50,16
1704067200014800000,ADD,149,BUY,41973.50,7
1704067200014900000,ADD,150,BUY,41973.50,18
1704067200015000000,ADD,151,BUY,41973.50,5
1704067200015100000,ADD,152,BUY,41974.00,8
1704067200015200000,ADD,153,BUY,41974.00,16
1704067200015300000,ADD,154,BUY,41974.00,14
1704067200015400000,ADD,155,BUY,41974.00,7
1704067200015500000,ADD,156,BUY,41974.00,4
1704067200015600000,ADD,157,BUY,41974.50,14
1704067200015700000,ADD,158,BUY,41974.50,12
1704067200015800000,ADD,159,BUY,41975.00,14
1704067200015900000,ADD,160,BUY,41975.00,15
1704067200016000000,ADD,161,BUY,41975.00,2
1704067200016100000,ADD,162,BUY,41975.00,4
1704067200016200000,ADD,163,BUY,41975.00,2
1704067200016300000,ADD,164,BUY,41975.50,11
1704067200016400000,ADD,165,BUY,41975.50,4
1704067200016500000,ADD,166,BUY,41975.50,8
1704067200016600000,ADD,167,BUY,41975.50,7
1704067200016700000,ADD,168,BUY,41975.50,7
1704067200016800000,ADD,169,BUY,41976.00,5
1704067200016900000,ADD,170,BUY,41976.00,14
1704067200017000000,ADD,171,BUY,41976.00,6
1704067200017100000,ADD,172,BUY,41976.00,9
1704067200017200000,ADD,173,BUY,41976.00,15
1704067200017300000,ADD,174,BUY,41976.50,3
1704067200017400000,ADD,175,BUY,41976.50,15
1704067200017500000,ADD,176,BUY,41976.50,18
1704067200017600000,ADD,177,BUY,41977.00,2
1704067200017700000,ADD,178,BUY,41977.00,18
1704067200017800000,ADD,179,BUY,41977.50,3
1704067200017900000,ADD,180,BUY,41977.50,8
1704067200018000000,ADD,181,BUY,41978.00,14
1704067200018100000,ADD,182,BUY,41978.00,16
1704067200018200000,ADD,183,BUY,41978.00,16
1704067200018300000,ADD,184,BUY,41978.50,13
1704067200018400000,ADD,185,BUY,41978.50,2
1704067200018500000,ADD,186,BUY,41978.50,6
